Workbook
Name MasterPlans: #REF!
Name MasterPlans: #REF!

Sheet PCW-Example

Sheet PCW-Template
D2: Project Cost Worksheet (PCW)- Horizontal Projects | G2: Worksheet Version: | H2: 1Q24 | P2: FOR MAJOR PROJECTS WITH NUMEROUS FUNDING SOURCES ONLY (See below.)
B4: SECTION 1 - PROJECT INFORMATION
C6: Project Name: | D6: Alameda Lane Reduction | H6: 75 character maximum
C8: Project Location: | D8: Alameda Ave from Franklin to Lincoln
C10: Instructions: | D10: Enter Agency specific instructions here about how to use this PCW. Leave blank if not applicable.
C14: Project Scope:
C18: Project Contact: | D18: Hadar Albo
C20: Year of Form: | D20: ='Data Validation'!D3 -> 2024
B22: SECTION 2 - COST ESTIMATE INFORMATION - What is the source of the cost data? (e.g. conceptual estimate, bids, etc.)
C24: Cost Estimate Data Source: | D24: Engingeers estiamte
C26: Cost Data Year: | D26: 2024
B28: SECTION 3 - TIMELINE / INFLATION & ESCALATION / RISK
C30: TIMELINE | D30: Enter YEAR (YYYY) | E30: No. of Yrs
C31: Year Land To Be Acquired: | E31: =IF(ISBLANK(D31),0,D31-'Data Validation'!$D$3) -> 0
C32: Year Design Starts: | E32: =IF(ISBLANK(D32),0,D32-'Data Validation'!$D$3) -> 0
C33: Year Construction Starts: | D33: 2025 | E33: =IF(ISBLANK(D33),0,D33-'Data Validation'!$D$3) -> 1
C35: INFLATION & ESCALATION | G35: AUTOMATIC PROJECT
C36: (Auto populates based on years) | G36: MANAGEMENT APPLICABLE?
G37: NO | H37: Default is "YES"
G38: If "NO," Briefly explain below.
C43: RISK / CONTINGENCY ADJUSTMENTS | D43: Select AVERAGE (AVG) or HIGH RISK | E43: % | G43: ART APPLICABLE?
C44: Land / Right of Way: | D44: AVG | E44: =IF(D44="AVG",'Data Validation'!C15,'Data Validation'!C16) -> 0 | G44: NO | H44: Default is "YES"
C45: Design: | D45: AVG | E45: =IF(D45="AVG",'Data Validation'!D15,'Data Validation'!D16) -> 0.05 | G45: If "NO," Briefly explain below.
C46: Construction: | D46: AVG | E46: =IF(D46="AVG",'Data Validation'!G15,'Data Validation'!G16) -> 0.1 | G46: Project is under $1 million
C47: Construction-Related: | D47: AVG | E47: =IF(D47="AVG",'Data Validation'!H15,'Data Validation'!H16) -> 0.1
C48: Project-Level: | D48: AVG | E48: =IF(D48="AVG",'Data Validation'!I15,'Data Validation'!I16) -> 0.05
L49: FUNDING NEEDS | M49: FUNDING SOURCES
B50: SECTION 4 - PROJECT BUDGET - For projects early in their life cycle, estimating at the general-level is appropriate. Provide detail if available. | K50: FOR MAJOR PROJECTS WITH NUMEROUS FUNDING SOURCES ONLY | L50: TOTAL PROJECT COST | M50: 37411 Rise Bond | N50: Vision Zero | O50: SRTS | P50: Safety and Neighborhood | Q50: Funding Source 5 | R50: Funding Source 6 | S50: Funding Source 7 | T50: Funding Source 8 | U50: Previously Funded | V50: Remaining to be Funded | X50: Overall Previous Funding Cross Check
L51: =L52 -> 450675.38 | M51: GO030 | N51: PQ015 | O51: PR008 | P51: PC022 | Q51: (Enter Existing Funding By Source Here) | R51: (Enter Existing Funding By Source Here) | S51: (Enter Existing Funding By Source Here) | T51: (Enter Existing Funding By Source Here) | U51: =SUM(M51:T51) -> 0 | V51: =U51-L51 -> -450675.38 | X51: =IF(SUBTOTAL(9,M52:T134)=U51,"OK","REVIEW") -> REVIEW
B52: Project Budget Subtotal | D52: =ROUNDUP(SUM(D53,D62,D72,D81,D94,D101,D111,D126,D133,D134,D137),-2) -> 450300 | E52: Rounded to $100 | K52: TOTAL | L52: =(SUM(D53,D62,D72,D81,D94,D101,D111,D126,D133,D134)) -> 450675.38 | M52: =SUBTOTAL(9,M53:M134) -> 250000 | N52: =SUBTOTAL(9,N53:N134) -> 210000 | O52: =SUBTOTAL(9,O53:O134) -> 3000 | P52: =SUBTOTAL(9,P53:P134) -> 66156.6 | Q52: =SUBTOTAL(9,Q53:Q134) -> 0 | R52: =SUBTOTAL(9,R53:R134) -> 0 | S52: =SUBTOTAL(9,S53:S134) -> 0 | T52: =SUBTOTAL(9,T53:T134) -> 0 | U52: =SUM(M52:T52) -> 529156.6 | V52: =U52-L52 -> 78481.22
B53: 01 - Project Level | D53: =SUM(D54:D61) -> 0 | K53: =B53 -> 01 - Project Level | L53: =D53 -> 0 | M53: =SUBTOTAL(9,M54:M61) -> 0 | N53: =SUBTOTAL(9,N54:N61) -> 0 | O53: =SUBTOTAL(9,O54:O61) -> 0 | P53: =SUBTOTAL(9,P54:P61) -> 0 | Q53: =SUBTOTAL(9,Q54:Q61) -> 0 | R53: =SUBTOTAL(9,R54:R61) -> 0 | S53: =SUBTOTAL(9,S54:S61) -> 0 | T53: =SUBTOTAL(9,T54:T61) -> 0 | U53: =SUM(M53:T53) -> 0 | V53: =U53-L53 -> 0
C54: Project Level - General | K54: =C54 -> Project Level - General | L54: =D54 -> 0 | U54: =SUM(M54:T54) -> 0 | V54: =U54-L54 -> 0
C55: Communications/Outreach | K55: =C55 -> Communications/Outreach | L55: =D55 -> 0 | U55: =SUM(M55:T55) -> 0 | V55: =U55-L55 -> 0
C56: Legal | K56: =C56 -> Legal | L56: =D56 -> 0 | U56: =SUM(M56:T56) -> 0 | V56: =U56-L56 -> 0
C57: Insurance | K57: =C57 -> Insurance | L57: =D57 -> 0 | U57: =SUM(M57:T57) -> 0 | V57: =U57-L57 -> 0
C58: Signage | K58: =C58 -> Signage | L58: =D58 -> 0 | U58: =SUM(M58:T58) -> 0 | V58: =U58-L58 -> 0
C59: Other | K59: =C59 -> Other | L59: =D59 -> 0 | U59: =SUM(M59:T59) -> 0 | V59: =U59-L59 -> 0
C60: ="Inflation adjust estimate to "&H2 -> Inflation adjust estimate to 1Q24 | D60: =IF(D26>='Data Validation'!D3,0,IF(ISBLANK(D26),"Enter Year of Cost Data Above",ROUND((SUBTOTAL(9,D54:D59)*'Data Validation'!D10),2))) -> 0 | E60: Design & Construction Inflation | K60: =C60 -> Inflation adjust estimate to 1Q24 | L60: =D60 -> 0 | U60: =SUM(M60:T60) -> 0 | V60: =U60-L60 -> 0
C61: ="Escalation @ "&TEXT('Cost Escalation'!D17*100,"0.00")&"% per/Yr for "&'PCW-Template'!E33&" Year(s)" -> Escalation @ 5.00% per/Yr for 1 Year(s) | D61: =ROUND((FV('Cost Escalation'!D14,E33,0,-SUM(D54:D60))-SUM(D54:D60)),2) -> 0 | E61: ="Assumes "&D33& " Construction" -> Assumes 2025 Construction | K61: =C61 -> Escalation @ 5.00% per/Yr for 1 Year(s) | L61: =D61 -> 0 | U61: =SUM(M61:T61) -> 0 | V61: =U61-L61 -> 0
B62: 02 - Project Management | D62: =SUM(D63:D71) -> 8863.05 | E62: City Project Management performed by Consultant | K62: =B62 -> 02 - Project Management | L62: =D62 -> 8863.05 | M62: =SUBTOTAL(9,M63:M71) -> 0 | N62: =SUBTOTAL(9,N63:N71) -> 0 | O62: =SUBTOTAL(9,O63:O71) -> 0 | P62: =SUBTOTAL(9,P63:P71) -> 0 | Q62: =SUBTOTAL(9,Q63:Q71) -> 0 | R62: =SUBTOTAL(9,R63:R71) -> 0 | S62: =SUBTOTAL(9,S63:S71) -> 0 | T62: =SUBTOTAL(9,T63:T71) -> 0 | U62: =SUM(M62:T62) -> 0 | V62: =U62-L62 -> -8863.05
...

Sheet Cost Escalation
B2: Enter Quarter of Data: | C2: Q1 | D2: <--- ALWAYS MAKE SURE THESE ARE SET UP TO WHAT YOU WANT
B3: Enter Year of Data: | C3: 2024
B4: Form Year: | C4: 2024
C5: =C3&C2 -> 2024Q1 | D5: <- Autocalculates based on your entry, used to drive calculations on inflation source pages.
B7: Real Estate Acquision Escalation
C8: Source: A bit lower than long run average annual growth rate, to account for slower fed interest rate cuts
C11: Cost Escalation Rate | D11: 0.05
B13: Design Cost Escalation
C14: Cost Escalation Rate | D14: =D17 -> 0.05 | E14: <-- ALWAYS MAKE SURE THIS IS SET TO WHAT YOU WANT, THIS IS QUARTERLY ESCALATION RATE
B16: Construction Cost Escalation
C17: Cost Inflation Rate | D17: 0.05 | E17: <-- ALWAYS MAKE SURE THIS IS SET TO WHAT YOU WANT, THIS IS QUARTERLY ESCALATION RATE
E18: Reasoning: a bit higher than vertical and parks due to heavy reliance on oil based and concrete based products, which have seen recent short-term increases.

Sheet Data Validation
B2: INFLATION & ESCALATION | N2: Notes to Self:
C3: Year of PCW Form: | D3: ='Cost Escalation'!C4 -> 2024 | N3: <--- Always make sure that this is accurate
C4: Year of Cost Data: | D4: ='PCW-Template'!D26 -> 2024
C5: Latest Cost Index Year: | D5: ='Cost Escalation'!C3 -> 2024
B7: CONSTRUCTION | E7: DESIGN | G7: REAL ESTATE
C8: ="Min. PPI Index for "&D4&" Cost Data:" -> Min. PPI Index for 2024 Cost Data: | D8: ='PPI-HiwaysandStreet(Horz Adj)'!K9 -> 148.467 | E8: ="Min. PPI Index for "&D4&" Cost Data:" -> Min. PPI Index for 2024 Cost Data: | F8: ='PPI-Horizontal Design'!K9 -> 138.485 | J8: ="Avg. Case-Schiller Index for "&D4&" Cost Data:" -> Avg. Case-Schiller Index for 2024 Cost Data: | K8: =IF('PCW-Template'!D26='Data Validation'!D3,'Data Validation'!K9,INDEX('Case-Schiller'!X9:X34,MATCH('PCW-Template'!D26,'Case-Schiller'!I9:I34,0))) -> 312.54281
C9: ="PPI Index as of "&'Cost Escalation'!C5&":" -> PPI Index as of 2024Q1: | D9: ='PPI-HiwaysandStreet(Horz Adj)'!J16 -> 150.082 | E9: ="PPI Index as of "&'Cost Escalation'!C5&":" -> PPI Index as of 2024Q1: | F9: ='PPI-Horizontal Design'!J16 -> 138.555 | J9: ="Case-Shiller Index as of "&'Cost Escalation'!C5&":" -> Case-Shiller Index as of 2024Q1: | K9: =INDEX('Case-Schiller'!X9:X45,MATCH(D5,'Case-Schiller'!I9:I45,0)) -> 312.54281
C10: Construction Inflation: | D10: =(D9-D8)/D8 -> 0.010877838 | E10: Design Inflation: | F10: =(F9-F8)/F8 -> 0.00050546991 | J10: Real Estate Inflation: | K10: =(K9-K8)/K8 -> 0
B13: RISK - CONTINGENCY PERCENTAGES
B14: DESCRIPTION | C14: LAND | D14: DESIGN | G14: CONSTRUCT | H14: CONSTRUCT-RELATED | I14: PROJECT
B15: AVG | C15: 0 | D15: 0.05 | G15: 0.1 | H15: 0.1 | I15: 0.05
B16: HIGH | C16: 0.5 | D16: 0.1 | G16: 0.15 | H16: 0.15 | I16: 0.1
B19: PUBLIC ART
B20: YES
B21: NO

Sheet Case-Schiller
H2: Case-Schiller Denver Home Price Index | I2: Nov. 2021 Index (latest) | K2: Nov. 2020 Index | M2: Nov. 2019 Index
I3: Index Value | J3: Y/Y Increase | K3: Index Value | L3: Y/Y Increase | M3: Index Value | N3: Y/Y Increase
H4: Case-Shiller Denver Index | I4: =T24 -> 293.99153 | J4: =(I4/K4)-1 -> 0.20227958 | K4: =T23 -> 244.52842 | L4: =(K4/M4)-1 -> 0.082904297 | M4: =T22 -> 225.80797 | N4: =(S22/S21)-1 -> 0.03456809
A5: Updates: published on the last Tuesday of every month with a 2 month lag.
A6: Published: | E6: Updated Date | F6: 45358
A7: Website Source: | B7: https://fred.stlouisfed.org/series/DNXRSA | F7: <-- copy and past this link into a web browser, then scroll over the graph and record values for needed months
I8: Index Values
A9: Effective date | D9: Month | E9: Year | F9: S&P CoreLogic Case-Shiller Denver Home Price NSA Index | J9: 1 | K9: 2 | L9: 3 | M9: 4 | N9: 5 | O9: 6 | P9: 7 | Q9: 8 | R9: 9 | S9: 10 | T9: 11 | U9: 12 | V9: Sum | W9: Data Points | X9: Average | Y9: Year over Year Growth
A10: Dec-2007 | B10: =A10+1 -> 39418 | C10: =B10-1 -> 39417 | D10: =MONTH(C10) -> 12 | E10: =YEAR(C10) -> 2007 | F10: 131.60757 | I10: 2007 | J10: =SUMIFS($F:$F,$E:$E,$I10,$D:$D,J$9) -> 0 | K10: =SUMIFS($F:$F,$E:$E,$I10,$D:$D,K$9) -> 0 | L10: =SUMIFS($F:$F,$E:$E,$I10,$D:$D,L$9) -> 0 | M10: =SUMIFS($F:$F,$E:$E,$I10,$D:$D,M$9) -> 0 | N10: =SUMIFS($F:$F,$E:$E,$I10,$D:$D,N$9) -> 0 | O10: =SUMIFS($F:$F,$E:$E,$I10,$D:$D,O$9) -> 0 | P10: =SUMIFS($F:$F,$E:$E,$I10,$D:$D,P$9) -> 0 | Q10: =SUMIFS($F:$F,$E:$E,$I10,$D:$D,Q$9) -> 0 | ... U10: =SUMIFS($F:$F,$E:$E,$I10,$D:$D,U$9) -> 131.60757 | V10: =SUM(J10:U10) -> 131.60757 | W10: =COUNTIFS(J10:U10,">"&0) -> 1 | X10: =V10/W10 -> 131.60757
A11: Jan-2008 | B11: =A11+1 -> 39449 | C11: =B11-1 -> 39448 | D11: =MONTH(C11) -> 1 | E11: =YEAR(C11) -> 2008 | F11: 130.93734 | I11: 2008 | J11: =SUMIFS($F:$F,$E:$E,$I11,$D:$D,J$9) -> 130.93734 | K11: =SUMIFS($F:$F,$E:$E,$I11,$D:$D,K$9) -> 130.25807 | L11: =SUMIFS($F:$F,$E:$E,$I11,$D:$D,L$9) -> 130.35156 | M11: =SUMIFS($F:$F,$E:$E,$I11,$D:$D,M$9) -> 130.19049 | N11: =SUMIFS($F:$F,$E:$E,$I11,$D:$D,N$9) -> 130.12314 | O11: =SUMIFS($F:$F,$E:$E,$I11,$D:$D,O$9) -> 130.18471 | P11: =SUMIFS($F:$F,$E:$E,$I11,$D:$D,P$9) -> 130.23331 | Q11: =SUMIFS($F:$F,$E:$E,$I11,$D:$D,Q$9) -> 129.61178 | ... U11: =SUMIFS($F:$F,$E:$E,$I11,$D:$D,U$9) -> 126.48713 | V11: =SUM(J11:U11) -> 1552.149 | W11: =COUNTIFS(J11:U11,">"&0) -> 12 | X11: =V11/W11 -> 129.34575 | Y11: =(X11/X10)-1 -> -0.017186127
A12: Feb-2008 | B12: =A12+1 -> 39480 | C12: =B12-1 -> 39479 | D12: =MONTH(C12) -> 2 | E12: =YEAR(C12) -> 2008 | F12: 130.25807 | I12: 2009 | J12: =SUMIFS($F:$F,$E:$E,$I12,$D:$D,J$9) -> 124.45564 | K12: =SUMIFS($F:$F,$E:$E,$I12,$D:$D,K$9) -> 123.12748 | L12: =SUMIFS($F:$F,$E:$E,$I12,$D:$D,L$9) -> 123.31489 | M12: =SUMIFS($F:$F,$E:$E,$I12,$D:$D,M$9) -> 123.73842 | N12: =SUMIFS($F:$F,$E:$E,$I12,$D:$D,N$9) -> 124.02331 | O12: =SUMIFS($F:$F,$E:$E,$I12,$D:$D,O$9) -> 125.27397 | P12: =SUMIFS($F:$F,$E:$E,$I12,$D:$D,P$9) -> 126.28853 | Q12: =SUMIFS($F:$F,$E:$E,$I12,$D:$D,Q$9) -> 127.02838 | ... U12: =SUMIFS($F:$F,$E:$E,$I12,$D:$D,U$9) -> 128.07057 | V12: =SUM(J12:U12) -> 1508.1907 | W12: =COUNTIFS(J12:U12,">"&0) -> 12 | X12: =V12/W12 -> 125.68256 | Y12: =(X12/X11)-1 -> -0.028320915
A13: Mar-2008 | B13: =A13+1 -> 39509 | C13: =B13-1 -> 39508 | D13: =MONTH(C13) -> 3 | E13: =YEAR(C13) -> 2008 | F13: 130.35156 | I13: 2010 | J13: =SUMIFS($F:$F,$E:$E,$I13,$D:$D,J$9) -> 127.89513 | K13: =SUMIFS($F:$F,$E:$E,$I13,$D:$D,K$9) -> 127.72907 | L13: =SUMIFS($F:$F,$E:$E,$I13,$D:$D,L$9) -> 128.34398 | M13: =SUMIFS($F:$F,$E:$E,$I13,$D:$D,M$9) -> 129.03095 | N13: =SUMIFS($F:$F,$E:$E,$I13,$D:$D,N$9) -> 128.30072 | O13: =SUMIFS($F:$F,$E:$E,$I13,$D:$D,O$9) -> 127.38053 | P13: =SUMIFS($F:$F,$E:$E,$I13,$D:$D,P$9) -> 126.18586 | Q13: =SUMIFS($F:$F,$E:$E,$I13,$D:$D,Q$9) -> 125.64553 | ... U13: =SUMIFS($F:$F,$E:$E,$I13,$D:$D,U$9) -> 125.07609 | V13: =SUM(J13:U13) -> 1521.1069 | W13: =COUNTIFS(J13:U13,">"&0) -> 12 | X13: =V13/W13 -> 126.75891 | Y13: =(X13/X12)-1 -> 0.0085640352
A14: Apr-2008 | B14: =A14+1 -> 39540 | C14: =B14-1 -> 39539 | D14: =MONTH(C14) -> 4 | E14: =YEAR(C14) -> 2008 | F14: 130.19049 | I14: 2011 | J14: =SUMIFS($F:$F,$E:$E,$I14,$D:$D,J$9) -> 124.99191 | K14: =SUMIFS($F:$F,$E:$E,$I14,$D:$D,K$9) -> 124.37826 | L14: =SUMIFS($F:$F,$E:$E,$I14,$D:$D,L$9) -> 123.27656 | M14: =SUMIFS($F:$F,$E:$E,$I14,$D:$D,M$9) -> 123.57596 | N14: =SUMIFS($F:$F,$E:$E,$I14,$D:$D,N$9) -> 123.77858 | O14: =SUMIFS($F:$F,$E:$E,$I14,$D:$D,O$9) -> 124.152 | P14: =SUMIFS($F:$F,$E:$E,$I14,$D:$D,P$9) -> 123.56032 | Q14: =SUMIFS($F:$F,$E:$E,$I14,$D:$D,Q$9) -> 123.81609 | ... U14: =SUMIFS($F:$F,$E:$E,$I14,$D:$D,U$9) -> 124.68251 | V14: =SUM(J14:U14) -> 1489.0636 | W14: =COUNTIFS(J14:U14,">"&0) -> 12 | X14: =V14/W14 -> 124.08864 | Y14: =(X14/X13)-1 -> -0.021065765
A15: May-2008 | B15: =A15+1 -> 39570 | C15: =B15-1 -> 39569 | D15: =MONTH(C15) -> 5 | E15: =YEAR(C15) -> 2008 | F15: 130.12314 | I15: 2012 | J15: =SUMIFS($F:$F,$E:$E,$I15,$D:$D,J$9) -> 125.11644 | K15: =SUMIFS($F:$F,$E:$E,$I15,$D:$D,K$9) -> 124.83067 | L15: =SUMIFS($F:$F,$E:$E,$I15,$D:$D,L$9) -> 126.10573 | M15: =SUMIFS($F:$F,$E:$E,$I15,$D:$D,M$9) -> 126.82325 | N15: =SUMIFS($F:$F,$E:$E,$I15,$D:$D,N$9) -> 128.09834 | O15: =SUMIFS($F:$F,$E:$E,$I15,$D:$D,O$9) -> 129.19517 | P15: =SUMIFS($F:$F,$E:$E,$I15,$D:$D,P$9) -> 130.37456 | Q15: =SUMIFS($F:$F,$E:$E,$I15,$D:$D,Q$9) -> 130.9531 | ... U15: =SUMIFS($F:$F,$E:$E,$I15,$D:$D,U$9) -> 135.39847 | V15: =SUM(J15:U15) -> 1556.9494 | W15: =COUNTIFS(J15:U15,">"&0) -> 12 | X15: =V15/W15 -> 129.74578 | Y15: =(X15/X14)-1 -> 0.045589562
A16: Jun-2008 | B16: =A16+1 -> 39601 | C16: =B16-1 -> 39600 | D16: =MONTH(C16) -> 6 | E16: =YEAR(C16) -> 2008 | F16: 130.18471 | I16: 2013 | J16: =SUMIFS($F:$F,$E:$E,$I16,$D:$D,J$9) -> 136.46781 | K16: =SUMIFS($F:$F,$E:$E,$I16,$D:$D,K$9) -> 136.98961 | L16: =SUMIFS($F:$F,$E:$E,$I16,$D:$D,L$9) -> 138.0089 | M16: =SUMIFS($F:$F,$E:$E,$I16,$D:$D,M$9) -> 139.02662 | N16: =SUMIFS($F:$F,$E:$E,$I16,$D:$D,N$9) -> 140.35365 | O16: =SUMIFS($F:$F,$E:$E,$I16,$D:$D,O$9) -> 141.41687 | P16: =SUMIFS($F:$F,$E:$E,$I16,$D:$D,P$9) -> 143.16116 | Q16: =SUMIFS($F:$F,$E:$E,$I16,$D:$D,Q$9) -> 144.53078 | ... U16: =SUMIFS($F:$F,$E:$E,$I16,$D:$D,U$9) -> 147.7027 | V16: =SUM(J16:U16) -> 1706.176 | W16: =COUNTIFS(J16:U16,">"&0) -> 12 | X16: =V16/W16 -> 142.18133 | Y16: =(X16/X15)-1 -> 0.095845494
A17: Jul-2008 | B17: =A17+1 -> 39631 | C17: =B17-1 -> 39630 | D17: =MONTH(C17) -> 7 | E17: =YEAR(C17) -> 2008 | F17: 130.23331 | I17: 2014 | J17: =SUMIFS($F:$F,$E:$E,$I17,$D:$D,J$9) -> 148.62366 | K17: =SUMIFS($F:$F,$E:$E,$I17,$D:$D,K$9) -> 149.15722 | L17: =SUMIFS($F:$F,$E:$E,$I17,$D:$D,L$9) -> 150.10434 | M17: =SUMIFS($F:$F,$E:$E,$I17,$D:$D,M$9) -> 150.98391 | N17: =SUMIFS($F:$F,$E:$E,$I17,$D:$D,N$9) -> 151.74037 | O17: =SUMIFS($F:$F,$E:$E,$I17,$D:$D,O$9) -> 152.40722 | P17: =SUMIFS($F:$F,$E:$E,$I17,$D:$D,P$9) -> 152.93436 | Q17: =SUMIFS($F:$F,$E:$E,$I17,$D:$D,Q$9) -> 153.93789 | ... U17: =SUMIFS($F:$F,$E:$E,$I17,$D:$D,U$9) -> 159.81155 | V17: =SUM(J17:U17) -> 1839.3366 | W17: =COUNTIFS(J17:U17,">"&0) -> 12 | X17: =V17/W17 -> 153.27805 | Y17: =(X17/X16)-1 -> 0.07804627
A18: Aug-2008 | B18: =A18+1 -> 39662 | C18: =B18-1 -> 39661 | D18: =MONTH(C18) -> 8 | E18: =YEAR(C18) -> 2008 | F18: 129.61178 | I18: 2015 | J18: =SUMIFS($F:$F,$E:$E,$I18,$D:$D,J$9) -> 161.0245 | K18: =SUMIFS($F:$F,$E:$E,$I18,$D:$D,K$9) -> 163.65771 | L18: =SUMIFS($F:$F,$E:$E,$I18,$D:$D,L$9) -> 164.48797 | M18: =SUMIFS($F:$F,$E:$E,$I18,$D:$D,M$9) -> 166.02975 | N18: =SUMIFS($F:$F,$E:$E,$I18,$D:$D,N$9) -> 166.77004 | O18: =SUMIFS($F:$F,$E:$E,$I18,$D:$D,O$9) -> 168.00867 | P18: =SUMIFS($F:$F,$E:$E,$I18,$D:$D,P$9) -> 168.87511 | Q18: =SUMIFS($F:$F,$E:$E,$I18,$D:$D,Q$9) -> 170.7158 | ... U18: =SUMIFS($F:$F,$E:$E,$I18,$D:$D,U$9) -> 176.19105 | V18: =SUM(J18:U18) -> 2027.3631 | W18: =COUNTIFS(J18:U18,">"&0) -> 12 | X18: =V18/W18 -> 168.94692 | Y18: =(X18/X17)-1 -> 0.10222515
A19: Sep-2008 | B19: =A19+1 -> 39693 | C19: =B19-1 -> 39692 | D19: =MONTH(C19) -> 9 | E19: =YEAR(C19) -> 2008 | F19: 128.75049 | I19: 2016 | J19: =SUMIFS($F:$F,$E:$E,$I19,$D:$D,J$9) -> 177.39326 | K19: =SUMIFS($F:$F,$E:$E,$I19,$D:$D,K$9) -> 179.18759 | L19: =SUMIFS($F:$F,$E:$E,$I19,$D:$D,L$9) -> 180.29816 | M19: =SUMIFS($F:$F,$E:$E,$I19,$D:$D,M$9) -> 181.3256 | N19: =SUMIFS($F:$F,$E:$E,$I19,$D:$D,N$9) -> 182.42454 | O19: =SUMIFS($F:$F,$E:$E,$I19,$D:$D,O$9) -> 183.55733 | P19: =SUMIFS($F:$F,$E:$E,$I19,$D:$D,P$9) -> 185.00783 | Q19: =SUMIFS($F:$F,$E:$E,$I19,$D:$D,Q$9) -> 186.13575 | ... U19: =SUMIFS($F:$F,$E:$E,$I19,$D:$D,U$9) -> 192.03255 | V19: =SUM(J19:U19) -> 2214.641 | W19: =COUNTIFS(J19:U19,">"&0) -> 12 | X19: =V19/W19 -> 184.55342 | Y19: =(X19/X18)-1 -> 0.092375112
A20: Oct-2008 | B20: =A20+1 -> 39723 | C20: =B20-1 -> 39722 | D20: =MONTH(C20) -> 10 | E20: =YEAR(C20) -> 2008 | F20: 127.6934 | I20: 2017 | J20: =SUMIFS($F:$F,$E:$E,$I20,$D:$D,J$9) -> 193.56966 | K20: =SUMIFS($F:$F,$E:$E,$I20,$D:$D,K$9) -> 194.43528 | L20: =SUMIFS($F:$F,$E:$E,$I20,$D:$D,L$9) -> 194.75413 | M20: =SUMIFS($F:$F,$E:$E,$I20,$D:$D,M$9) -> 195.5807 | N20: =SUMIFS($F:$F,$E:$E,$I20,$D:$D,N$9) -> 196.53114 | O20: =SUMIFS($F:$F,$E:$E,$I20,$D:$D,O$9) -> 197.42446 | P20: =SUMIFS($F:$F,$E:$E,$I20,$D:$D,P$9) -> 198.57132 | Q20: =SUMIFS($F:$F,$E:$E,$I20,$D:$D,Q$9) -> 199.89835 | ... U20: =SUMIFS($F:$F,$E:$E,$I20,$D:$D,U$9) -> 206.53228 | V20: =SUM(J20:U20) -> 2385.5611 | W20: =COUNTIFS(J20:U20,">"&0) -> 12 | X20: =V20/W20 -> 198.79676 | Y20: =(X20/X19)-1 -> 0.077177346
A21: Nov-2008 | B21: =A21+1 -> 39754 | C21: =B21-1 -> 39753 | D21: =MONTH(C21) -> 11 | E21: =YEAR(C21) -> 2008 | F21: 127.32756 | I21: 2018 | J21: =SUMIFS($F:$F,$E:$E,$I21,$D:$D,J$9) -> 208.35625 | K21: =SUMIFS($F:$F,$E:$E,$I21,$D:$D,K$9) -> 210.54582 | L21: =SUMIFS($F:$F,$E:$E,$I21,$D:$D,L$9) -> 211.01809 | M21: =SUMIFS($F:$F,$E:$E,$I21,$D:$D,M$9) -> 211.91023 | N21: =SUMIFS($F:$F,$E:$E,$I21,$D:$D,N$9) -> 212.84487 | O21: =SUMIFS($F:$F,$E:$E,$I21,$D:$D,O$9) -> 213.56151 | P21: =SUMIFS($F:$F,$E:$E,$I21,$D:$D,P$9) -> 214.48545 | Q21: =SUMIFS($F:$F,$E:$E,$I21,$D:$D,Q$9) -> 215.37902 | ... U21: =SUMIFS($F:$F,$E:$E,$I21,$D:$D,U$9) -> 218.20573 | V21: =SUM(J21:U21) -> 2567.1548 | W21: =COUNTIFS(J21:U21,">"&0) -> 12 | X21: =V21/W21 -> 213.92956 | Y21: =(X21/X20)-1 -> 0.076121996
A22: Dec-2008 | B22: =A22+1 -> 39784 | C22: =B22-1 -> 39783 | D22: =MONTH(C22) -> 12 | E22: =YEAR(C22) -> 2008 | F22: 126.48713 | I22: 2019 | J22: =SUMIFS($F:$F,$E:$E,$I22,$D:$D,J$9) -> 218.98595 | K22: =SUMIFS($F:$F,$E:$E,$I22,$D:$D,K$9) -> 220.45832 | L22: =SUMIFS($F:$F,$E:$E,$I22,$D:$D,L$9) -> 219.62795 | M22: =SUMIFS($F:$F,$E:$E,$I22,$D:$D,M$9) -> 219.55417 | N22: =SUMIFS($F:$F,$E:$E,$I22,$D:$D,N$9) -> 219.94663 | O22: =SUMIFS($F:$F,$E:$E,$I22,$D:$D,O$9) -> 220.42929 | P22: =SUMIFS($F:$F,$E:$E,$I22,$D:$D,P$9) -> 220.88442 | Q22: =SUMIFS($F:$F,$E:$E,$I22,$D:$D,Q$9) -> 221.72454 | ... U22: =SUMIFS($F:$F,$E:$E,$I22,$D:$D,U$9) -> 226.74608 | V22: =SUM(J22:U22) -> 2661.7646 | W22: =COUNTIFS(J22:U22,">"&0) -> 12 | X22: =V22/W22 -> 221.81372 | Y22: =(X22/X21)-1 -> 0.036853971
A23: Jan-2009 | B23: =A23+1 -> 39815 | C23: =B23-1 -> 39814 | D23: =MONTH(C23) -> 1 | E23: =YEAR(C23) -> 2009 | F23: 124.45564 | I23: 2020 | J23: =SUMIFS($F:$F,$E:$E,$I23,$D:$D,J$9) -> 227.46925 | K23: =SUMIFS($F:$F,$E:$E,$I23,$D:$D,K$9) -> 228.24646 | L23: =SUMIFS($F:$F,$E:$E,$I23,$D:$D,L$9) -> 227.58148 | M23: =SUMIFS($F:$F,$E:$E,$I23,$D:$D,M$9) -> 227.77825 | N23: =SUMIFS($F:$F,$E:$E,$I23,$D:$D,N$9) -> 228.03937 | O23: =SUMIFS($F:$F,$E:$E,$I23,$D:$D,O$9) -> 228.85686 | P23: =SUMIFS($F:$F,$E:$E,$I23,$D:$D,P$9) -> 230.28702 | Q23: =SUMIFS($F:$F,$E:$E,$I23,$D:$D,Q$9) -> 233.48581 | ... U23: =SUMIFS($F:$F,$E:$E,$I23,$D:$D,U$9) -> 248.23411 | V23: =SUM(J23:U23) -> 2801.8985 | W23: =COUNTIFS(J23:U23,">"&0) -> 12 | X23: =V23/W23 -> 233.49154 | Y23: =(X23/X22)-1 -> 0.052646968
A24: Feb-2009 | B24: =A24+1 -> 39846 | C24: =B24-1 -> 39845 | D24: =MONTH(C24) -> 2 | E24: =YEAR(C24) -> 2009 | F24: 123.12748 | I24: 2021 | J24: =SUMIFS($F:$F,$E:$E,$I24,$D:$D,J$9) -> 250.82893 | K24: =SUMIFS($F:$F,$E:$E,$I24,$D:$D,K$9) -> 254.6099 | L24: =SUMIFS($F:$F,$E:$E,$I24,$D:$D,L$9) -> 258.32096 | M24: =SUMIFS($F:$F,$E:$E,$I24,$D:$D,M$9) -> 262.3228 | N24: =SUMIFS($F:$F,$E:$E,$I24,$D:$D,N$9) -> 267.26628 | O24: =SUMIFS($F:$F,$E:$E,$I24,$D:$D,O$9) -> 273.341 | P24: =SUMIFS($F:$F,$E:$E,$I24,$D:$D,P$9) -> 278.99506 | Q24: =SUMIFS($F:$F,$E:$E,$I24,$D:$D,Q$9) -> 283.71311 | ... U24: =SUMIFS($F:$F,$E:$E,$I24,$D:$D,U$9) -> 299.10966 | V24: =SUM(J24:U24) -> 3299.4754 | W24: =COUNTIFS(J24:U24,">"&0) -> 12 | X24: =IF(W24=0,X23,V24/W24) -> 274.95628 | Y24: =(X24/X23)-1 -> 0.17758565
A25: Mar-2009 | B25: =A25+1 -> 39874 | C25: =B25-1 -> 39873 | D25: =MONTH(C25) -> 3 | E25: =YEAR(C25) -> 2009 | F25: 123.31489 | I25: 2022 | J25: =SUMIFS($F:$F,$E:$E,$I25,$D:$D,J$9) -> 303.26937 | K25: =SUMIFS($F:$F,$E:$E,$I25,$D:$D,K$9) -> 311.51429 | L25: =SUMIFS($F:$F,$E:$E,$I25,$D:$D,L$9) -> 319.18671 | M25: =SUMIFS($F:$F,$E:$E,$I25,$D:$D,M$9) -> 323.73747 | N25: =SUMIFS($F:$F,$E:$E,$I25,$D:$D,N$9) -> 326.02938 | O25: =SUMIFS($F:$F,$E:$E,$I25,$D:$D,O$9) -> 325.68239 | P25: =SUMIFS($F:$F,$E:$E,$I25,$D:$D,P$9) -> 322.16357 | Q25: =SUMIFS($F:$F,$E:$E,$I25,$D:$D,Q$9) -> 317.6411 | ... U25: =SUMIFS($F:$F,$E:$E,$I25,$D:$D,U$9) -> 310.16394 | V25: =SUM(J25:U25) -> 3798.6687 | W25: =COUNTIFS(J25:U25,">"&0) -> 12 | X25: =IF(W25=0,X24,V25/W25) -> 316.55573 | Y25: =(X25/X24)-1 -> 0.15129475
A26: Apr-2009 | B26: =A26+1 -> 39905 | C26: =B26-1 -> 39904 | D26: =MONTH(C26) -> 4 | E26: =YEAR(C26) -> 2009 | F26: 123.73842 | I26: 2023 | J26: =SUMIFS($F:$F,$E:$E,$I26,$D:$D,J$9) -> 306.55985 | K26: =SUMIFS($F:$F,$E:$E,$I26,$D:$D,K$9) -> 307.87059 | L26: =SUMIFS($F:$F,$E:$E,$I26,$D:$D,L$9) -> 307.68974 | M26: =SUMIFS($F:$F,$E:$E,$I26,$D:$D,M$9) -> 308.77264 | N26: =SUMIFS($F:$F,$E:$E,$I26,$D:$D,N$9) -> 309.90841 | O26: =SUMIFS($F:$F,$E:$E,$I26,$D:$D,O$9) -> 311.22389 | P26: =SUMIFS($F:$F,$E:$E,$I26,$D:$D,P$9) -> 312.84474 | Q26: =SUMIFS($F:$F,$E:$E,$I26,$D:$D,Q$9) -> 315.62392 | ... U26: =SUMIFS($F:$F,$E:$E,$I26,$D:$D,U$9) -> 317.50703 | V26: =SUM(J26:U26) -> 3750.5137 | W26: =COUNTIFS(J26:U26,">"&0) -> 12 | X26: =IF(W26=0,X25,V26/W26) -> 312.54281 | Y26: =(X26/X25)-1 -> -0.012676815
A27: May-2009 | B27: =A27+1 -> 39935 | C27: =B27-1 -> 39934 | D27: =MONTH(C27) -> 5 | E27: =YEAR(C27) -> 2009 | F27: 124.02331 | I27: 2024 | V27: =SUM(J27:U27) -> 0 | W27: =COUNTIFS(J27:U27,">"&0) -> 0 | X27: =IF(W27=0,X26,V27/W27) -> 312.54281 | Y27: =(X27/X26)-1 -> 0
A28: Jun-2009 | B28: =A28+1 -> 39966 | C28: =B28-1 -> 39965 | D28: =MONTH(C28) -> 6 | E28: =YEAR(C28) -> 2009 | F28: 125.27397 | I28: 2025 | V28: =SUM(J28:U28) -> 0 | W28: =COUNTIFS(J28:U28,">"&0) -> 0 | X28: =IF(W28=0,X27,V28/W28) -> 312.54281 | Y28: =(X28/X27)-1 -> 0
A29: Jul-2009 | B29: =A29+1 -> 39996 | C29: =B29-1 -> 39995 | D29: =MONTH(C29) -> 7 | E29: =YEAR(C29) -> 2009 | F29: 126.28853 | I29: 2026 | V29: =SUM(J29:U29) -> 0 | W29: =COUNTIFS(J29:U29,">"&0) -> 0 | X29: =IF(W29=0,X28,V29/W29) -> 312.54281 | Y29: =(X29/X28)-1 -> 0
A30: Aug-2009 | B30: =A30+1 -> 40027 | C30: =B30-1 -> 40026 | D30: =MONTH(C30) -> 8 | E30: =YEAR(C30) -> 2009 | F30: 127.02838 | I30: 2027 | V30: =SUM(J30:U30) -> 0 | W30: =COUNTIFS(J30:U30,">"&0) -> 0 | X30: =IF(W30=0,X29,V30/W30) -> 312.54281 | Y30: =(X30/X29)-1 -> 0
A31: Sep-2009 | B31: =A31+1 -> 40058 | C31: =B31-1 -> 40057 | D31: =MONTH(C31) -> 9 | E31: =YEAR(C31) -> 2009 | F31: 127.28289 | I31: 2028 | V31: =SUM(J31:U31) -> 0 | W31: =COUNTIFS(J31:U31,">"&0) -> 0 | X31: =IF(W31=0,X30,V31/W31) -> 312.54281 | Y31: =(X31/X30)-1 -> 0
A32: Oct-2009 | B32: =A32+1 -> 40088 | C32: =B32-1 -> 40087 | D32: =MONTH(C32) -> 10 | E32: =YEAR(C32) -> 2009 | F32: 127.59228 | I32: 2029 | V32: =SUM(J32:U32) -> 0 | W32: =COUNTIFS(J32:U32,">"&0) -> 0 | X32: =IF(W32=0,X31,V32/W32) -> 312.54281 | Y32: =(X32/X31)-1 -> 0
A33: Nov-2009 | B33: =A33+1 -> 40119 | C33: =B33-1 -> 40118 | D33: =MONTH(C33) -> 11 | E33: =YEAR(C33) -> 2009 | F33: 127.99435 | I33: 2030 | V33: =SUM(J33:U33) -> 0 | W33: =COUNTIFS(J33:U33,">"&0) -> 0 | X33: =IF(W33=0,X32,V33/W33) -> 312.54281 | Y33: =(X33/X32)-1 -> 0
A34: Dec-2009 | B34: =A34+1 -> 40149 | C34: =B34-1 -> 40148 | D34: =MONTH(C34) -> 12 | E34: =YEAR(C34) -> 2009 | F34: 128.07057 | I34: ^^^^^ Add rows above this line ^^^^^
A35: Jan-2010 | B35: =A35+1 -> 40180 | C35: =B35-1 -> 40179 | D35: =MONTH(C35) -> 1 | E35: =YEAR(C35) -> 2010 | F35: 127.89513
A36: Feb-2010 | B36: =A36+1 -> 40211 | C36: =B36-1 -> 40210 | D36: =MONTH(C36) -> 2 | E36: =YEAR(C36) -> 2010 | F36: 127.72907
A37: Mar-2010 | B37: =A37+1 -> 40239 | C37: =B37-1 -> 40238 | D37: =MONTH(C37) -> 3 | E37: =YEAR(C37) -> 2010 | F37: 128.34398
A38: Apr-2010 | B38: =A38+1 -> 40270 | C38: =B38-1 -> 40269 | D38: =MONTH(C38) -> 4 | E38: =YEAR(C38) -> 2010 | F38: 129.03095
A39: May-2010 | B39: =A39+1 -> 40300 | C39: =B39-1 -> 40299 | D39: =MONTH(C39) -> 5 | E39: =YEAR(C39) -> 2010 | F39: 128.30072
A40: Jun-2010 | B40: =A40+1 -> 40331 | C40: =B40-1 -> 40330 | D40: =MONTH(C40) -> 6 | E40: =YEAR(C40) -> 2010 | F40: 127.38053
A41: Jul-2010 | B41: =A41+1 -> 40361 | C41: =B41-1 -> 40360 | D41: =MONTH(C41) -> 7 | E41: =YEAR(C41) -> 2010 | F41: 126.18586
...

Sheet PPI-Horizontal Design
B2: Producer's Price Index | G2: Month : | H2: 1 | I2: 2 | J2: 3 | K2: 4 | L2: 5 | M2: 6 | N2: 7 | O2: 8 | P2: 9 | Q2: 10 | R2: 11 | S2: 12
G3: Quarter: | H3: Q1 | I3: Q1 | J3: Q1 | K3: Q2 | L3: Q2 | M3: Q2 | N3: Q3 | O3: Q3 | P3: Q3 | Q3: Q4 | R3: Q4 | S3: Q4
B5: Source: | C5: https://fred.stlouisfed.org/series/WPU4532
B7: AS OF Q1- 2022, THIS IS NOW THE INDEX TO USE TO ADJUST HISTORICAL RATES FOR HORIZONTAL CONSTRUCTION PROJECTS
K8: Min Index During Year | L8: Max Index During Year | M8: Average Index During Year
I9: Year of Cost Data (linked to user input): | J9: ='PCW-Template'!D26 -> 2024 | K9: =_xlfn.MINIFS(F21:F500,E21:E500,$J$9) -> 138.485 | L9: =_xlfn.MAXIFS(F21:F500,E21:E500,$J$9) -> 138.555 | M9: =AVERAGEIFS(F21:F500,E21:E500,J9) -> 138.52
B10: FRED Graph Observations | J10: Change from Current: | K10: =(J16/K9)-1 -> 0.00050546991 | L10: =(J16/L9)-1 -> 0 | M10: =(J16/M9)-1 -> 0.00025267109
B11: Federal Reserve Economic Data | J11: 2021 | K11: =_xlfn.MINIFS(F23:F502,E23:E502,$J$11) -> 123.3 | L11: =_xlfn.MAXIFS(F23:F502,E23:E502,$J$11) -> 124.794 | M11: =AVERAGEIFS(F23:F502,E23:E502,J11) -> 124.05533
B12: Link: https://fred.stlouisfed.org | J12: Change from Current: | K12: =(J16/K11)-1 -> 0.12372263 | L12: =(J16/L11)-1 -> 0.11026972 | M12: =(J16/M11)-1 -> 0.11688064
B13: Help: https://fredhelp.stlouisfed.org | J13: 2022 | K13: =_xlfn.MINIFS(F25:F504,E25:E504,$J$13) -> 128.962 | L13: =_xlfn.MAXIFS(F25:F504,E25:E504,$J$13) -> 132.413 | M13: =AVERAGEIFS(F25:F504,E25:E504,J13) -> 130.8825
B14: Economic Research Division | J14: Change from Current: | K14: =(J16/K13)-1 -> 0.074386253 | L14: =(J16/L13)-1 -> 0.046385174 | M14: =(J16/M13)-1 -> 0.058621282
B15: Federal Reserve Bank of St. Louis
I16: Current Index: | J16: {=LOOKUP(2,1/(F21:F500<>""),F21:F500)} -> 138.555
B17: WPU4532 | C17: Producer Price Index by Commodity: Professional Services (Partial): Engineering Services, Index Mar 2009=100, Monthly, Not Seasonally Adjusted
B19: Frequency: Monthly
B20: observation_date | C20: Month | D20: Quarter | E20: Year of Observation | F20: WPU4532 | J20: Year | K20: Min Index During Year | L20: Max Index During Year | M20: Average Index During Year | N20: Min. % of Avg.
B21: 39873 | C21: =MONTH(B21) -> 3 | D21: =INDEX($H$3:$S$3,MATCH(C21,$H$2:$S$2,0)) -> Q1 | E21: =YEAR(B21) -> 2009 | F21: 100 | J21: 2009 | K21: =_xlfn.MINIFS($F$21:$F$500,$E$21:$E$500,$J21) -> 100 | L21: =_xlfn.MAXIFS($F$21:$F$500,$E$21:$E$500,$J21) -> 100.2 | M21: =AVERAGEIFS($F$21:$F$500,$E$21:$E$500,$J21) -> 100.15 | N21: =K21/M21 -> 0.99850225
B22: 39904 | C22: =MONTH(B22) -> 4 | D22: =INDEX($H$3:$S$3,MATCH(C22,$H$2:$S$2,0)) -> Q2 | E22: =YEAR(B22) -> 2009 | F22: 100.1 | J22: 2010 | K22: =_xlfn.MINIFS($F$21:$F$500,$E$21:$E$500,$J22) -> 99.8 | L22: =_xlfn.MAXIFS($F$21:$F$500,$E$21:$E$500,$J22) -> 100.9 | M22: =AVERAGEIFS($F$21:$F$500,$E$21:$E$500,$J22) -> 100.49167 | N22: =K22/M22 -> 0.99311717
B23: 39934 | C23: =MONTH(B23) -> 5 | D23: =INDEX($H$3:$S$3,MATCH(C23,$H$2:$S$2,0)) -> Q2 | E23: =YEAR(B23) -> 2009 | F23: 100.1 | J23: 2011 | K23: =_xlfn.MINIFS($F$21:$F$500,$E$21:$E$500,$J23) -> 100.8 | L23: =_xlfn.MAXIFS($F$21:$F$500,$E$21:$E$500,$J23) -> 102.4 | M23: =AVERAGEIFS($F$21:$F$500,$E$21:$E$500,$J23) -> 101.65833 | N23: =K23/M23 -> 0.99155668
B24: 39965 | C24: =MONTH(B24) -> 6 | D24: =INDEX($H$3:$S$3,MATCH(C24,$H$2:$S$2,0)) -> Q2 | E24: =YEAR(B24) -> 2009 | F24: 100.1 | J24: 2012 | K24: =_xlfn.MINIFS($F$21:$F$500,$E$21:$E$500,$J24) -> 102.5 | L24: =_xlfn.MAXIFS($F$21:$F$500,$E$21:$E$500,$J24) -> 104.3 | M24: =AVERAGEIFS($F$21:$F$500,$E$21:$E$500,$J24) -> 103.30833 | N24: =K24/M24 -> 0.99217553
B25: 39995 | C25: =MONTH(B25) -> 7 | D25: =INDEX($H$3:$S$3,MATCH(C25,$H$2:$S$2,0)) -> Q3 | E25: =YEAR(B25) -> 2009 | F25: 100.2 | J25: 2013 | K25: =_xlfn.MINIFS($F$21:$F$500,$E$21:$E$500,$J25) -> 104 | L25: =_xlfn.MAXIFS($F$21:$F$500,$E$21:$E$500,$J25) -> 105.4 | M25: =AVERAGEIFS($F$21:$F$500,$E$21:$E$500,$J25) -> 104.93333 | N25: =K25/M25 -> 0.99110546
B26: 40026 | C26: =MONTH(B26) -> 8 | D26: =INDEX($H$3:$S$3,MATCH(C26,$H$2:$S$2,0)) -> Q3 | E26: =YEAR(B26) -> 2009 | F26: 100.2 | J26: 2014 | K26: =_xlfn.MINIFS($F$21:$F$500,$E$21:$E$500,$J26) -> 105.7 | L26: =_xlfn.MAXIFS($F$21:$F$500,$E$21:$E$500,$J26) -> 107.7 | M26: =AVERAGEIFS($F$21:$F$500,$E$21:$E$500,$J26) -> 106.58333 | N26: =K26/M26 -> 0.99171228
B27: 40057 | C27: =MONTH(B27) -> 9 | D27: =INDEX($H$3:$S$3,MATCH(C27,$H$2:$S$2,0)) -> Q3 | E27: =YEAR(B27) -> 2009 | F27: 100.2 | J27: 2015 | K27: =_xlfn.MINIFS($F$21:$F$500,$E$21:$E$500,$J27) -> 107.8 | L27: =_xlfn.MAXIFS($F$21:$F$500,$E$21:$E$500,$J27) -> 110.2 | M27: =AVERAGEIFS($F$21:$F$500,$E$21:$E$500,$J27) -> 109.35833 | N27: =K27/M27 -> 0.98575021
B28: 40087 | C28: =MONTH(B28) -> 10 | D28: =INDEX($H$3:$S$3,MATCH(C28,$H$2:$S$2,0)) -> Q4 | E28: =YEAR(B28) -> 2009 | F28: 100.2 | J28: 2016 | K28: =_xlfn.MINIFS($F$21:$F$500,$E$21:$E$500,$J28) -> 110.6 | L28: =_xlfn.MAXIFS($F$21:$F$500,$E$21:$E$500,$J28) -> 112.4 | M28: =AVERAGEIFS($F$21:$F$500,$E$21:$E$500,$J28) -> 111.46667 | N28: =K28/M28 -> 0.99222488
B29: 40118 | C29: =MONTH(B29) -> 11 | D29: =INDEX($H$3:$S$3,MATCH(C29,$H$2:$S$2,0)) -> Q4 | E29: =YEAR(B29) -> 2009 | F29: 100.2 | J29: 2017 | K29: =_xlfn.MINIFS($F$21:$F$500,$E$21:$E$500,$J29) -> 112.9 | L29: =_xlfn.MAXIFS($F$21:$F$500,$E$21:$E$500,$J29) -> 115.5 | M29: =AVERAGEIFS($F$21:$F$500,$E$21:$E$500,$J29) -> 114.00833 | N29: =K29/M29 -> 0.99027849
B30: 40148 | C30: =MONTH(B30) -> 12 | D30: =INDEX($H$3:$S$3,MATCH(C30,$H$2:$S$2,0)) -> Q4 | E30: =YEAR(B30) -> 2009 | F30: 100.2 | J30: 2018 | K30: =_xlfn.MINIFS($F$21:$F$500,$E$21:$E$500,$J30) -> 115.7 | L30: =_xlfn.MAXIFS($F$21:$F$500,$E$21:$E$500,$J30) -> 117.9 | M30: =AVERAGEIFS($F$21:$F$500,$E$21:$E$500,$J30) -> 116.98333 | N30: =K30/M30 -> 0.98902978
B31: 40179 | C31: =MONTH(B31) -> 1 | D31: =INDEX($H$3:$S$3,MATCH(C31,$H$2:$S$2,0)) -> Q1 | E31: =YEAR(B31) -> 2010 | F31: 100.2 | J31: 2019 | K31: =_xlfn.MINIFS($F$21:$F$500,$E$21:$E$500,$J31) -> 118.9 | L31: =_xlfn.MAXIFS($F$21:$F$500,$E$21:$E$500,$J31) -> 120.6 | M31: =AVERAGEIFS($F$21:$F$500,$E$21:$E$500,$J31) -> 120.025 | N31: =K31/M31 -> 0.99062695
B32: 40210 | C32: =MONTH(B32) -> 2 | D32: =INDEX($H$3:$S$3,MATCH(C32,$H$2:$S$2,0)) -> Q1 | E32: =YEAR(B32) -> 2010 | F32: 99.8 | J32: 2020 | K32: =_xlfn.MINIFS($F$21:$F$500,$E$21:$E$500,$J32) -> 119.7 | L32: =_xlfn.MAXIFS($F$21:$F$500,$E$21:$E$500,$J32) -> 122.1 | M32: =AVERAGEIFS($F$21:$F$500,$E$21:$E$500,$J32) -> 120.53333 | N32: =K32/M32 -> 0.99308628
... B36: 40330 | C36: =MONTH(B36) -> 6 | D36: =INDEX($H$3:$S$3,MATCH(C36,$H$2:$S$2,0)) -> Q2 | E36: =YEAR(B36) -> 2010 | F36: 100.6 | J36: 2024 | K36: =_xlfn.MINIFS($F$21:$F$500,$E$21:$E$500,$J36) -> 138.485 | L36: =_xlfn.MAXIFS($F$21:$F$500,$E$21:$E$500,$J36) -> 138.555 | M36: =AVERAGEIFS($F$21:$F$500,$E$21:$E$500,$J36) -> 138.52 | N36: =K36/M36 -> 0.99974733
B37: 40360 | C37: =MONTH(B37) -> 7 | D37: =INDEX($H$3:$S$3,MATCH(C37,$H$2:$S$2,0)) -> Q3 | E37: =YEAR(B37) -> 2010 | F37: 100.8
B38: 40391 | C38: =MONTH(B38) -> 8 | D38: =INDEX($H$3:$S$3,MATCH(C38,$H$2:$S$2,0)) -> Q3 | E38: =YEAR(B38) -> 2010 | F38: 100.8
B39: 40422 | C39: =MONTH(B39) -> 9 | D39: =INDEX($H$3:$S$3,MATCH(C39,$H$2:$S$2,0)) -> Q3 | E39: =YEAR(B39) -> 2010 | F39: 100.8
B40: 40452 | C40: =MONTH(B40) -> 10 | D40: =INDEX($H$3:$S$3,MATCH(C40,$H$2:$S$2,0)) -> Q4 | E40: =YEAR(B40) -> 2010 | F40: 100.8
B41: 40483 | C41: =MONTH(B41) -> 11 | D41: =INDEX($H$3:$S$3,MATCH(C41,$H$2:$S$2,0)) -> Q4 | E41: =YEAR(B41) -> 2010 | F41: 100.9
B42: 40513 | C42: =MONTH(B42) -> 12 | D42: =INDEX($H$3:$S$3,MATCH(C42,$H$2:$S$2,0)) -> Q4 | E42: =YEAR(B42) -> 2010 | F42: 100.6
B43: 40544 | C43: =MONTH(B43) -> 1 | D43: =INDEX($H$3:$S$3,MATCH(C43,$H$2:$S$2,0)) -> Q1 | E43: =YEAR(B43) -> 2011 | F43: 100.8
B44: 40575 | C44: =MONTH(B44) -> 2 | D44: =INDEX($H$3:$S$3,MATCH(C44,$H$2:$S$2,0)) -> Q1 | E44: =YEAR(B44) -> 2011 | F44: 101
B45: 40603 | C45: =MONTH(B45) -> 3 | D45: =INDEX($H$3:$S$3,MATCH(C45,$H$2:$S$2,0)) -> Q1 | E45: =YEAR(B45) -> 2011 | F45: 101.1
B46: 40634 | C46: =MONTH(B46) -> 4 | D46: =INDEX($H$3:$S$3,MATCH(C46,$H$2:$S$2,0)) -> Q2 | E46: =YEAR(B46) -> 2011 | F46: 101.2
B47: 40664 | C47: =MONTH(B47) -> 5 | D47: =INDEX($H$3:$S$3,MATCH(C47,$H$2:$S$2,0)) -> Q2 | E47: =YEAR(B47) -> 2011 | F47: 101.1
...

Sheet PPI-HiwaysandStreet(Horz Adj)
B2: Producer's Price Index | G2: Month : | H2: 1 | I2: 2 | J2: 3 | K2: 4 | L2: 5 | M2: 6 | N2: 7 | O2: 8 | P2: 9 | Q2: 10 | R2: 11 | S2: 12
G3: Quarter: | H3: Q1 | I3: Q1 | J3: Q1 | K3: Q2 | L3: Q2 | M3: Q2 | N3: Q3 | O3: Q3 | P3: Q3 | Q3: Q4 | R3: Q4 | S3: Q4
B5: Source: | C5: https://fred.stlouisfed.org/series/WPUIP231231
B7: AS OF Q1- 2022, THIS IS NOW THE INDEX TO USE TO ADJUST HISTORICAL RATES FOR HORIZONTAL CONSTRUCTION PROJECTS
K8: Min Index During Year | L8: Max Index During Year | M8: Average Index During Year
I9: Year of Cost Data (linked to user input): | J9: ='PCW-Template'!D26 -> 2024 | K9: =_xlfn.MINIFS(F21:F500,E21:E500,$J$9) -> 148.467 | L9: =_xlfn.MAXIFS(F21:F500,E21:E500,$J$9) -> 150.082 | M9: =AVERAGEIFS(F21:F500,E21:E500,J9) -> 149.2745
B10: FRED Graph Observations | J10: Change from Current: | K10: =(J16/K9)-1 -> 0.010877838 | L10: =(J16/L9)-1 -> 0 | M10: =(J16/M9)-1 -> 0.0054094973
B11: Federal Reserve Economic Data | J11: 2021 | K11: =_xlfn.MINIFS(F23:F502,E23:E502,$J$11) -> 114.3 | L11: =_xlfn.MAXIFS(F23:F502,E23:E502,$J$11) -> 133.448 | M11: =AVERAGEIFS(F23:F502,E23:E502,J11) -> 126.22258
B12: Link: https://fred.stlouisfed.org | J12: Change from Current: | K12: =(J16/K11)-1 -> 0.31305337 | L12: =(J16/L11)-1 -> 0.1246478 | M12: =(J16/M11)-1 -> 0.18902653
B13: Help: https://fredhelp.stlouisfed.org | J13: 2022 | K13: =_xlfn.MINIFS(F25:F504,E25:E504,$J$13) -> 137.764 | L13: =_xlfn.MAXIFS(F25:F504,E25:E504,$J$13) -> 152.389 | M13: =AVERAGEIFS(F25:F504,E25:E504,J13) -> 146.51317
B14: Economic Research Division | J14: Change from Current: | K14: =(J16/K13)-1 -> 0.08941378 | L14: =(J16/L13)-1 -> -0.015138888 | M14: =(J16/M13)-1 -> 0.024358448
B15: Federal Reserve Bank of St. Louis
I16: Current Index: | J16: {=LOOKUP(2,1/(F21:F500<>""),F21:F500)} -> 150.082
B17: WPUIP231231 | C17: Producer Price Index by Commodity: Inputs to Industries: Net Inputs to Highways and Streets, Excluding Capital Investment, Labor, and Imports, Index Dec 2014=100, Monthly, Not Seasonally Adjusted
B19: Frequency: Monthly
B20: observation_date | C20: Month | D20: Quarter | E20: Year of Observation | F20: WPUIP231231 | J20: Year | K20: Min Index During Year | L20: Max Index During Year | M20: Average Index During Year | N20: Min. % of Avg.
B21: 41974 | C21: =MONTH(B21) -> 12 | D21: =INDEX($H$3:$S$3,MATCH(C21,$H$2:$S$2,0)) -> Q4 | E21: =YEAR(B21) -> 2014 | F21: 100 | J21: 2014 | K21: =_xlfn.MINIFS($F$21:$F$500,$E$21:$E$500,$J21) -> 100 | L21: =_xlfn.MAXIFS($F$21:$F$500,$E$21:$E$500,$J21) -> 100 | M21: =AVERAGEIFS($F$21:$F$500,$E$21:$E$500,$J21) -> 100 | N21: =K21/M21 -> 1
B22: 42005 | C22: =MONTH(B22) -> 1 | D22: =INDEX($H$3:$S$3,MATCH(C22,$H$2:$S$2,0)) -> Q1 | E22: =YEAR(B22) -> 2015 | F22: 98 | J22: 2015 | K22: =_xlfn.MINIFS($F$21:$F$500,$E$21:$E$500,$J22) -> 96 | L22: =_xlfn.MAXIFS($F$21:$F$500,$E$21:$E$500,$J22) -> 100.6 | M22: =AVERAGEIFS($F$21:$F$500,$E$21:$E$500,$J22) -> 98.766667 | N22: =K22/M22 -> 0.97198785
B23: 42036 | C23: =MONTH(B23) -> 2 | D23: =INDEX($H$3:$S$3,MATCH(C23,$H$2:$S$2,0)) -> Q1 | E23: =YEAR(B23) -> 2015 | F23: 98.2 | J23: 2016 | K23: =_xlfn.MINIFS($F$21:$F$500,$E$21:$E$500,$J23) -> 95.1 | L23: =_xlfn.MAXIFS($F$21:$F$500,$E$21:$E$500,$J23) -> 98.5 | M23: =AVERAGEIFS($F$21:$F$500,$E$21:$E$500,$J23) -> 97.283333 | N23: =K23/M23 -> 0.97755696
B24: 42064 | C24: =MONTH(B24) -> 3 | D24: =INDEX($H$3:$S$3,MATCH(C24,$H$2:$S$2,0)) -> Q1 | E24: =YEAR(B24) -> 2015 | F24: 98.9 | J24: 2017 | K24: =_xlfn.MINIFS($F$21:$F$500,$E$21:$E$500,$J24) -> 99.6 | L24: =_xlfn.MAXIFS($F$21:$F$500,$E$21:$E$500,$J24) -> 102.8 | M24: =AVERAGEIFS($F$21:$F$500,$E$21:$E$500,$J24) -> 101.03333 | N24: =K24/M24 -> 0.98581326
B25: 42095 | C25: =MONTH(B25) -> 4 | D25: =INDEX($H$3:$S$3,MATCH(C25,$H$2:$S$2,0)) -> Q2 | E25: =YEAR(B25) -> 2015 | F25: 99 | J25: 2018 | K25: =_xlfn.MINIFS($F$21:$F$500,$E$21:$E$500,$J25) -> 104.1 | L25: =_xlfn.MAXIFS($F$21:$F$500,$E$21:$E$500,$J25) -> 111.1 | M25: =AVERAGEIFS($F$21:$F$500,$E$21:$E$500,$J25) -> 108.08333 | N25: =K25/M25 -> 0.96314572
B26: 42125 | C26: =MONTH(B26) -> 5 | D26: =INDEX($H$3:$S$3,MATCH(C26,$H$2:$S$2,0)) -> Q2 | E26: =YEAR(B26) -> 2015 | F26: 100.5 | J26: 2019 | K26: =_xlfn.MINIFS($F$21:$F$500,$E$21:$E$500,$J26) -> 107.2 | L26: =_xlfn.MAXIFS($F$21:$F$500,$E$21:$E$500,$J26) -> 110.8 | M26: =AVERAGEIFS($F$21:$F$500,$E$21:$E$500,$J26) -> 109.35833 | N26: =K26/M26 -> 0.98026366
B27: 42156 | C27: =MONTH(B27) -> 6 | D27: =INDEX($H$3:$S$3,MATCH(C27,$H$2:$S$2,0)) -> Q2 | E27: =YEAR(B27) -> 2015 | F27: 100.6 | J27: 2020 | K27: =_xlfn.MINIFS($F$21:$F$500,$E$21:$E$500,$J27) -> 103.1 | L27: =_xlfn.MAXIFS($F$21:$F$500,$E$21:$E$500,$J27) -> 111.4 | M27: =AVERAGEIFS($F$21:$F$500,$E$21:$E$500,$J27) -> 107.68333 | N27: =K27/M27 -> 0.95743693
B28: 42186 | C28: =MONTH(B28) -> 7 | D28: =INDEX($H$3:$S$3,MATCH(C28,$H$2:$S$2,0)) -> Q3 | E28: =YEAR(B28) -> 2015 | F28: 100.6 | J28: 2021 | K28: =_xlfn.MINIFS($F$21:$F$500,$E$21:$E$500,$J28) -> 114.3 | L28: =_xlfn.MAXIFS($F$21:$F$500,$E$21:$E$500,$J28) -> 133.448 | M28: =AVERAGEIFS($F$21:$F$500,$E$21:$E$500,$J28) -> 126.22258 | N28: =K28/M28 -> 0.90554318
B29: 42217 | C29: =MONTH(B29) -> 8 | D29: =INDEX($H$3:$S$3,MATCH(C29,$H$2:$S$2,0)) -> Q3 | E29: =YEAR(B29) -> 2015 | F29: 100 | J29: 2022 | K29: =_xlfn.MINIFS($F$21:$F$500,$E$21:$E$500,$J29) -> 137.764 | L29: =_xlfn.MAXIFS($F$21:$F$500,$E$21:$E$500,$J29) -> 152.389 | M29: =AVERAGEIFS($F$21:$F$500,$E$21:$E$500,$J29) -> 146.51317 | N29: =K29/M29 -> 0.94028409
B30: 42248 | C30: =MONTH(B30) -> 9 | D30: =INDEX($H$3:$S$3,MATCH(C30,$H$2:$S$2,0)) -> Q3 | E30: =YEAR(B30) -> 2015 | F30: 98.2
B31: 42278 | C31: =MONTH(B31) -> 10 | D31: =INDEX($H$3:$S$3,MATCH(C31,$H$2:$S$2,0)) -> Q4 | E31: =YEAR(B31) -> 2015 | F31: 97.8 | J31: 3 year Avg. Calc.
B32: 42309 | C32: =MONTH(B32) -> 11 | D32: =INDEX($H$3:$S$3,MATCH(C32,$H$2:$S$2,0)) -> Q4 | E32: =YEAR(B32) -> 2015 | F32: 97.4 | J32: =J26 -> 2019 | K32: =K26 -> 107.2
B33: 42339 | C33: =MONTH(B33) -> 12 | D33: =INDEX($H$3:$S$3,MATCH(C33,$H$2:$S$2,0)) -> Q4 | E33: =YEAR(B33) -> 2015 | F33: 96 | J33: Latest | K33: =J16 -> 150.082
B34: 42370 | C34: =MONTH(B34) -> 1 | D34: =INDEX($H$3:$S$3,MATCH(C34,$H$2:$S$2,0)) -> Q1 | E34: =YEAR(B34) -> 2016 | F34: 95.7 | J34: 3 Year Avg. | K34: =(K33/K32)-1 -> 0.40001866
B35: 42401 | C35: =MONTH(B35) -> 2 | D35: =INDEX($H$3:$S$3,MATCH(C35,$H$2:$S$2,0)) -> Q1 | E35: =YEAR(B35) -> 2016 | F35: 95.1
B36: 42430 | C36: =MONTH(B36) -> 3 | D36: =INDEX($H$3:$S$3,MATCH(C36,$H$2:$S$2,0)) -> Q1 | E36: =YEAR(B36) -> 2016 | F36: 95.7
B37: 42461 | C37: =MONTH(B37) -> 4 | D37: =INDEX($H$3:$S$3,MATCH(C37,$H$2:$S$2,0)) -> Q2 | E37: =YEAR(B37) -> 2016 | F37: 96.5
B38: 42491 | C38: =MONTH(B38) -> 5 | D38: =INDEX($H$3:$S$3,MATCH(C38,$H$2:$S$2,0)) -> Q2 | E38: =YEAR(B38) -> 2016 | F38: 97.4
B39: 42522 | C39: =MONTH(B39) -> 6 | D39: =INDEX($H$3:$S$3,MATCH(C39,$H$2:$S$2,0)) -> Q2 | E39: =YEAR(B39) -> 2016 | F39: 98.5
B40: 42552 | C40: =MONTH(B40) -> 7 | D40: =INDEX($H$3:$S$3,MATCH(C40,$H$2:$S$2,0)) -> Q3 | E40: =YEAR(B40) -> 2016 | F40: 98.5
B41: 42583 | C41: =MONTH(B41) -> 8 | D41: =INDEX($H$3:$S$3,MATCH(C41,$H$2:$S$2,0)) -> Q3 | E41: =YEAR(B41) -> 2016 | F41: 98.1
B42: 42614 | C42: =MONTH(B42) -> 9 | D42: =INDEX($H$3:$S$3,MATCH(C42,$H$2:$S$2,0)) -> Q3 | E42: =YEAR(B42) -> 2016 | F42: 98
B43: 42644 | C43: =MONTH(B43) -> 10 | D43: =INDEX($H$3:$S$3,MATCH(C43,$H$2:$S$2,0)) -> Q4 | E43: =YEAR(B43) -> 2016 | F43: 98.1
B44: 42675 | C44: =MONTH(B44) -> 11 | D44: =INDEX($H$3:$S$3,MATCH(C44,$H$2:$S$2,0)) -> Q4 | E44: =YEAR(B44) -> 2016 | F44: 97.5
...
